import org.junit.FixMethodOrder;
import org.junit.Test;
import org.junit.runners.MethodSorters;

@FixMethodOrder(MethodSorters.NAME_ASCENDING)
public class RegressionTest0 {

    public static boolean debug = false;

    @Test
    public void test1() throws Throwable {
        if (debug)
            System.out.format("%n%s%n", "RegressionTest0.test1");
        java.lang.Object obj0 = new java.lang.Object();
        java.lang.Class<?> wildcardClass1 = obj0.getClass();
        org.junit.Assert.assertNotNull(wildcardClass1);
    }

    @Test
    public void test2() throws Throwable {
        if (debug)
            System.out.format("%n%s%n", "RegressionTest0.test2");
        TestClass1 testClass1_0 = new TestClass1();
        java.lang.Class<?> wildcardClass1 = testClass1_0.getClass();
        org.junit.Assert.assertNotNull(wildcardClass1);
    }

    @Test
    public void test3() throws Throwable {
        if (debug)
            System.out.format("%n%s%n", "RegressionTest0.test3");
        TestClass1 testClass1_0 = new TestClass1();
        // The following exception was thrown during execution in test generation
        try {
            int int3 = testClass1_0.add((int) '4', 0);
            org.junit.Assert.fail("Expected exception of type java.lang.ArithmeticException; message: / by zero");
        } catch (java.lang.ArithmeticException e) {
            // Expected exception.
        }
    }

    @Test
    public void test4() throws Throwable {
        if (debug)
            System.out.format("%n%s%n", "RegressionTest0.test4");
        TestClass1 testClass1_0 = new TestClass1();
        // The following exception was thrown during execution in test generation
        try {
            int int3 = testClass1_0.add((int) 'a', (-1));
            org.junit.Assert.fail("Expected exception of type java.lang.ArithmeticException; message: / by zero");
        } catch (java.lang.ArithmeticException e) {
            // Expected exception.
        }
    }

    @Test
    public void test5() throws Throwable {
        if (debug)
            System.out.format("%n%s%n", "RegressionTest0.test5");
        TestClass1 testClass1_0 = new TestClass1();
        // The following exception was thrown during execution in test generation
        try {
            int int3 = testClass1_0.add((int) (short) 100, 100);
            org.junit.Assert.fail("Expected exception of type java.lang.ArithmeticException; message: / by zero");
        } catch (java.lang.ArithmeticException e) {
            // Expected exception.
        }
    }

    @Test
    public void test6() throws Throwable {
        if (debug)
            System.out.format("%n%s%n", "RegressionTest0.test6");
        TestClass1 testClass1_0 = new TestClass1();
        // The following exception was thrown during execution in test generation
        try {
            int int3 = testClass1_0.add(1, 0);
            org.junit.Assert.fail("Expected exception of type java.lang.ArithmeticException; message: / by zero");
        } catch (java.lang.ArithmeticException e) {
            // Expected exception.
        }
    }

    @Test
    public void test7() throws Throwable {
        if (debug)
            System.out.format("%n%s%n", "RegressionTest0.test7");
        TestClass1 testClass1_0 = new TestClass1();
        // The following exception was thrown during execution in test generation
        try {
            int int3 = testClass1_0.add((int) (byte) -1, (int) 'a');
            org.junit.Assert.fail("Expected exception of type java.lang.ArithmeticException; message: / by zero");
        } catch (java.lang.ArithmeticException e) {
            // Expected exception.
        }
    }

    @Test
    public void test8() throws Throwable {
        if (debug)
            System.out.format("%n%s%n", "RegressionTest0.test8");
        TestClass1 testClass1_0 = new TestClass1();
        // The following exception was thrown during execution in test generation
        try {
            int int3 = testClass1_0.add((int) ' ', (int) '#');
            org.junit.Assert.fail("Expected exception of type java.lang.ArithmeticException; message: / by zero");
        } catch (java.lang.ArithmeticException e) {
            // Expected exception.
        }
    }

    @Test
    public void test9() throws Throwable {
        if (debug)
            System.out.format("%n%s%n", "RegressionTest0.test9");
        TestClass1 testClass1_0 = new TestClass1();
        // The following exception was thrown during execution in test generation
        try {
            int int3 = testClass1_0.add((int) (byte) 100, 10);
            org.junit.Assert.fail("Expected exception of type java.lang.ArithmeticException; message: / by zero");
        } catch (java.lang.ArithmeticException e) {
            // Expected exception.
        }
    }
}

